INFO 2025-08-09 16:03:13,476 autoreload 1294098 136893895458944 Watching for file changes with StatReloader
INFO 2025-08-09 16:12:23,355 autoreload 1307485 139784276869248 Watching for file changes with StatReloader
INFO 2025-08-09 16:28:12,956 autoreload 1329898 130815336312960 Watching for file changes with StatReloader
INFO 2025-08-09 16:29:07,978 autoreload 1331414 140083836035200 Watching for file changes with StatReloader
INFO 2025-08-09 16:35:17,846 autoreload 1331414 140083836035200 /home/hader/skillswap-backend/skillswap/settings.py changed, reloading.
INFO 2025-08-09 16:35:18,331 autoreload 1339769 130427218235520 Watching for file changes with StatReloader
INFO 2025-08-09 16:35:52,191 autoreload 1339769 130427218235520 /home/hader/skillswap-backend/accounts/models.py changed, reloading.
INFO 2025-08-09 16:35:52,652 autoreload 1340715 123647691137152 Watching for file changes with StatReloader
INFO 2025-08-09 16:35:58,987 autoreload 1340715 123647691137152 /home/hader/skillswap-backend/accounts/models.py changed, reloading.
INFO 2025-08-09 16:35:59,465 autoreload 1340858 131487748624512 Watching for file changes with StatReloader
INFO 2025-08-09 16:36:03,726 autoreload 1340858 131487748624512 /home/hader/skillswap-backend/accounts/models.py changed, reloading.
INFO 2025-08-09 16:36:04,177 autoreload 1340989 124548125032576 Watching for file changes with StatReloader
INFO 2025-08-09 16:36:19,671 autoreload 1340989 124548125032576 /home/hader/skillswap-backend/skillswap/settings.py changed, reloading.
INFO 2025-08-09 16:36:20,114 autoreload 1341464 129176246870144 Watching for file changes with StatReloader
INFO 2025-08-09 16:36:25,447 autoreload 1341464 129176246870144 /home/hader/skillswap-backend/skillswap/settings.py changed, reloading.
INFO 2025-08-09 16:36:25,907 autoreload 1341657 125208276516992 Watching for file changes with StatReloader
INFO 2025-08-09 16:39:59,725 basehttp 1341657 125208172336832 "GET /api/ HTTP/1.1" 200 1553
ERROR 2025-08-09 16:39:59,765 log 1341657 125208172336832 Internal Server Error: /api/skills/categories/
Traceback (most recent call last):
  File "/home/hader/skillswap-backend/venv/lib/python3.12/site-packages/django/db/backends/utils.py", line 105, in _execute
    return self.cursor.execute(sql, params)
           ^^^^^^^^^^^^^^^^^^^^^^^^^^^^^^^^
psycopg2.errors.UndefinedTable: relation "skills_category" does not exist
LINE 1: ...."is_active", "skills_category"."created_at" FROM "skills_ca...
                                                             ^


The above exception was the direct cause of the following exception:

Traceback (most recent call last):
  File "/home/hader/skillswap-backend/venv/lib/python3.12/site-packages/django/core/handlers/exception.py", line 55, in inner
    response = get_response(request)
               ^^^^^^^^^^^^^^^^^^^^^
  File "/home/hader/skillswap-backend/venv/lib/python3.12/site-packages/django/core/handlers/base.py", line 197, in _get_response
    response = wrapped_callback(request, *callback_args, **callback_kwargs)
               ^^^^^^^^^^^^^^^^^^^^^^^^^^^^^^^^^^^^^^^^^^^^^^^^^^^^^^^^^^^^
  File "/home/hader/skillswap-backend/venv/lib/python3.12/site-packages/django/views/decorators/csrf.py", line 65, in _view_wrapper
    return view_func(request, *args, **kwargs)
           ^^^^^^^^^^^^^^^^^^^^^^^^^^^^^^^^^^^
  File "/home/hader/skillswap-backend/venv/lib/python3.12/site-packages/django/views/generic/base.py", line 104, in view
    return self.dispatch(request, *args, **kwargs)
           ^^^^^^^^^^^^^^^^^^^^^^^^^^^^^^^^^^^^^^^
  File "/home/hader/skillswap-backend/venv/lib/python3.12/site-packages/rest_framework/views.py", line 509, in dispatch
    response = self.handle_exception(exc)
               ^^^^^^^^^^^^^^^^^^^^^^^^^^
  File "/home/hader/skillswap-backend/venv/lib/python3.12/site-packages/rest_framework/views.py", line 469, in handle_exception
    self.raise_uncaught_exception(exc)
  File "/home/hader/skillswap-backend/venv/lib/python3.12/site-packages/rest_framework/views.py", line 480, in raise_uncaught_exception
    raise exc
  File "/home/hader/skillswap-backend/venv/lib/python3.12/site-packages/rest_framework/views.py", line 506, in dispatch
    response = handler(request, *args, **kwargs)
               ^^^^^^^^^^^^^^^^^^^^^^^^^^^^^^^^^
  File "/home/hader/skillswap-backend/skills/views.py", line 53, in get
    return Response(serializer.data)
                    ^^^^^^^^^^^^^^^
  File "/home/hader/skillswap-backend/venv/lib/python3.12/site-packages/rest_framework/serializers.py", line 795, in data
    ret = super().data
          ^^^^^^^^^^^^
  File "/home/hader/skillswap-backend/venv/lib/python3.12/site-packages/rest_framework/serializers.py", line 249, in data
    self._data = self.to_representation(self.instance)
                 ^^^^^^^^^^^^^^^^^^^^^^^^^^^^^^^^^^^^^
  File "/home/hader/skillswap-backend/venv/lib/python3.12/site-packages/rest_framework/serializers.py", line 713, in to_representation
    return [
           ^
  File "/home/hader/skillswap-backend/venv/lib/python3.12/site-packages/django/db/models/query.py", line 400, in __iter__
    self._fetch_all()
  File "/home/hader/skillswap-backend/venv/lib/python3.12/site-packages/django/db/models/query.py", line 1928, in _fetch_all
    self._result_cache = list(self._iterable_class(self))
                         ^^^^^^^^^^^^^^^^^^^^^^^^^^^^^^^^
  File "/home/hader/skillswap-backend/venv/lib/python3.12/site-packages/django/db/models/query.py", line 91, in __iter__
    results = compiler.execute_sql(
              ^^^^^^^^^^^^^^^^^^^^^
  File "/home/hader/skillswap-backend/venv/lib/python3.12/site-packages/django/db/models/sql/compiler.py", line 1562, in execute_sql
    cursor.execute(sql, params)
  File "/home/hader/skillswap-backend/venv/lib/python3.12/site-packages/django/db/backends/utils.py", line 79, in execute
    return self._execute_with_wrappers(
           ^^^^^^^^^^^^^^^^^^^^^^^^^^^^
  File "/home/hader/skillswap-backend/venv/lib/python3.12/site-packages/django/db/backends/utils.py", line 92, in _execute_with_wrappers
    return executor(sql, params, many, context)
           ^^^^^^^^^^^^^^^^^^^^^^^^^^^^^^^^^^^^
  File "/home/hader/skillswap-backend/venv/lib/python3.12/site-packages/django/db/backends/utils.py", line 100, in _execute
    with self.db.wrap_database_errors:
  File "/home/hader/skillswap-backend/venv/lib/python3.12/site-packages/django/db/utils.py", line 91, in __exit__
    raise dj_exc_value.with_traceback(traceback) from exc_value
  File "/home/hader/skillswap-backend/venv/lib/python3.12/site-packages/django/db/backends/utils.py", line 105, in _execute
    return self.cursor.execute(sql, params)
           ^^^^^^^^^^^^^^^^^^^^^^^^^^^^^^^^
django.db.utils.ProgrammingError: relation "skills_category" does not exist
LINE 1: ...."is_active", "skills_category"."created_at" FROM "skills_ca...
                                                             ^

ERROR 2025-08-09 16:39:59,769 basehttp 1341657 125208172336832 "GET /api/skills/categories/ HTTP/1.1" 500 145
WARNING 2025-08-09 16:39:59,796 log 1341657 125208172336832 Bad Request: /api/skills/
WARNING 2025-08-09 16:39:59,796 basehttp 1341657 125208172336832 "GET /api/skills/ HTTP/1.1" 400 215
WARNING 2025-08-09 16:39:59,821 log 1341657 125208172336832 Not Found: /api/accounts/users/
WARNING 2025-08-09 16:39:59,821 basehttp 1341657 125208172336832 "GET /api/accounts/users/ HTTP/1.1" 404 179
ERROR 2025-08-09 16:39:59,861 log 1341657 125208172336832 Internal Server Error: /api/points/packages/
Traceback (most recent call last):
  File "/home/hader/skillswap-backend/venv/lib/python3.12/site-packages/django/db/backends/utils.py", line 105, in _execute
    return self.cursor.execute(sql, params)
           ^^^^^^^^^^^^^^^^^^^^^^^^^^^^^^^^
psycopg2.errors.UndefinedTable: relation "points_pointspackage" does not exist
LINE 1: ...active", "points_pointspackage"."created_at" FROM "points_po...
                                                             ^


The above exception was the direct cause of the following exception:

Traceback (most recent call last):
  File "/home/hader/skillswap-backend/venv/lib/python3.12/site-packages/django/core/handlers/exception.py", line 55, in inner
    response = get_response(request)
               ^^^^^^^^^^^^^^^^^^^^^
  File "/home/hader/skillswap-backend/venv/lib/python3.12/site-packages/django/core/handlers/base.py", line 197, in _get_response
    response = wrapped_callback(request, *callback_args, **callback_kwargs)
               ^^^^^^^^^^^^^^^^^^^^^^^^^^^^^^^^^^^^^^^^^^^^^^^^^^^^^^^^^^^^
  File "/home/hader/skillswap-backend/venv/lib/python3.12/site-packages/django/views/decorators/csrf.py", line 65, in _view_wrapper
    return view_func(request, *args, **kwargs)
           ^^^^^^^^^^^^^^^^^^^^^^^^^^^^^^^^^^^
  File "/home/hader/skillswap-backend/venv/lib/python3.12/site-packages/django/views/generic/base.py", line 104, in view
    return self.dispatch(request, *args, **kwargs)
           ^^^^^^^^^^^^^^^^^^^^^^^^^^^^^^^^^^^^^^^
  File "/home/hader/skillswap-backend/venv/lib/python3.12/site-packages/rest_framework/views.py", line 509, in dispatch
    response = self.handle_exception(exc)
               ^^^^^^^^^^^^^^^^^^^^^^^^^^
  File "/home/hader/skillswap-backend/venv/lib/python3.12/site-packages/rest_framework/views.py", line 469, in handle_exception
    self.raise_uncaught_exception(exc)
  File "/home/hader/skillswap-backend/venv/lib/python3.12/site-packages/rest_framework/views.py", line 480, in raise_uncaught_exception
    raise exc
  File "/home/hader/skillswap-backend/venv/lib/python3.12/site-packages/rest_framework/views.py", line 506, in dispatch
    response = handler(request, *args, **kwargs)
               ^^^^^^^^^^^^^^^^^^^^^^^^^^^^^^^^^
  File "/home/hader/skillswap-backend/points/views.py", line 27, in get
    return Response(serializer.data, status=status.HTTP_200_OK)
                    ^^^^^^^^^^^^^^^
  File "/home/hader/skillswap-backend/venv/lib/python3.12/site-packages/rest_framework/serializers.py", line 795, in data
    ret = super().data
          ^^^^^^^^^^^^
  File "/home/hader/skillswap-backend/venv/lib/python3.12/site-packages/rest_framework/serializers.py", line 249, in data
    self._data = self.to_representation(self.instance)
                 ^^^^^^^^^^^^^^^^^^^^^^^^^^^^^^^^^^^^^
  File "/home/hader/skillswap-backend/venv/lib/python3.12/site-packages/rest_framework/serializers.py", line 713, in to_representation
    return [
           ^
  File "/home/hader/skillswap-backend/venv/lib/python3.12/site-packages/django/db/models/query.py", line 400, in __iter__
    self._fetch_all()
  File "/home/hader/skillswap-backend/venv/lib/python3.12/site-packages/django/db/models/query.py", line 1928, in _fetch_all
    self._result_cache = list(self._iterable_class(self))
                         ^^^^^^^^^^^^^^^^^^^^^^^^^^^^^^^^
  File "/home/hader/skillswap-backend/venv/lib/python3.12/site-packages/django/db/models/query.py", line 91, in __iter__
    results = compiler.execute_sql(
              ^^^^^^^^^^^^^^^^^^^^^
  File "/home/hader/skillswap-backend/venv/lib/python3.12/site-packages/django/db/models/sql/compiler.py", line 1562, in execute_sql
    cursor.execute(sql, params)
  File "/home/hader/skillswap-backend/venv/lib/python3.12/site-packages/django/db/backends/utils.py", line 79, in execute
    return self._execute_with_wrappers(
           ^^^^^^^^^^^^^^^^^^^^^^^^^^^^
  File "/home/hader/skillswap-backend/venv/lib/python3.12/site-packages/django/db/backends/utils.py", line 92, in _execute_with_wrappers
    return executor(sql, params, many, context)
           ^^^^^^^^^^^^^^^^^^^^^^^^^^^^^^^^^^^^
  File "/home/hader/skillswap-backend/venv/lib/python3.12/site-packages/django/db/backends/utils.py", line 100, in _execute
    with self.db.wrap_database_errors:
  File "/home/hader/skillswap-backend/venv/lib/python3.12/site-packages/django/db/utils.py", line 91, in __exit__
    raise dj_exc_value.with_traceback(traceback) from exc_value
  File "/home/hader/skillswap-backend/venv/lib/python3.12/site-packages/django/db/backends/utils.py", line 105, in _execute
    return self.cursor.execute(sql, params)
           ^^^^^^^^^^^^^^^^^^^^^^^^^^^^^^^^
django.db.utils.ProgrammingError: relation "points_pointspackage" does not exist
LINE 1: ...active", "points_pointspackage"."created_at" FROM "points_po...
                                                             ^

ERROR 2025-08-09 16:39:59,862 basehttp 1341657 125208172336832 "GET /api/points/packages/ HTTP/1.1" 500 145
ERROR 2025-08-09 16:39:59,885 log 1341657 125208172336832 Internal Server Error: /api/skills/categories/
Traceback (most recent call last):
  File "/home/hader/skillswap-backend/venv/lib/python3.12/site-packages/django/db/backends/utils.py", line 105, in _execute
    return self.cursor.execute(sql, params)
           ^^^^^^^^^^^^^^^^^^^^^^^^^^^^^^^^
psycopg2.errors.UndefinedTable: relation "skills_category" does not exist
LINE 1: ...."is_active", "skills_category"."created_at" FROM "skills_ca...
                                                             ^


The above exception was the direct cause of the following exception:

Traceback (most recent call last):
  File "/home/hader/skillswap-backend/venv/lib/python3.12/site-packages/django/core/handlers/exception.py", line 55, in inner
    response = get_response(request)
               ^^^^^^^^^^^^^^^^^^^^^
  File "/home/hader/skillswap-backend/venv/lib/python3.12/site-packages/django/core/handlers/base.py", line 197, in _get_response
    response = wrapped_callback(request, *callback_args, **callback_kwargs)
               ^^^^^^^^^^^^^^^^^^^^^^^^^^^^^^^^^^^^^^^^^^^^^^^^^^^^^^^^^^^^
  File "/home/hader/skillswap-backend/venv/lib/python3.12/site-packages/django/views/decorators/csrf.py", line 65, in _view_wrapper
    return view_func(request, *args, **kwargs)
           ^^^^^^^^^^^^^^^^^^^^^^^^^^^^^^^^^^^
  File "/home/hader/skillswap-backend/venv/lib/python3.12/site-packages/django/views/generic/base.py", line 104, in view
    return self.dispatch(request, *args, **kwargs)
           ^^^^^^^^^^^^^^^^^^^^^^^^^^^^^^^^^^^^^^^
  File "/home/hader/skillswap-backend/venv/lib/python3.12/site-packages/rest_framework/views.py", line 509, in dispatch
    response = self.handle_exception(exc)
               ^^^^^^^^^^^^^^^^^^^^^^^^^^
  File "/home/hader/skillswap-backend/venv/lib/python3.12/site-packages/rest_framework/views.py", line 469, in handle_exception
    self.raise_uncaught_exception(exc)
  File "/home/hader/skillswap-backend/venv/lib/python3.12/site-packages/rest_framework/views.py", line 480, in raise_uncaught_exception
    raise exc
  File "/home/hader/skillswap-backend/venv/lib/python3.12/site-packages/rest_framework/views.py", line 506, in dispatch
    response = handler(request, *args, **kwargs)
               ^^^^^^^^^^^^^^^^^^^^^^^^^^^^^^^^^
  File "/home/hader/skillswap-backend/skills/views.py", line 53, in get
    return Response(serializer.data)
                    ^^^^^^^^^^^^^^^
  File "/home/hader/skillswap-backend/venv/lib/python3.12/site-packages/rest_framework/serializers.py", line 795, in data
    ret = super().data
          ^^^^^^^^^^^^
  File "/home/hader/skillswap-backend/venv/lib/python3.12/site-packages/rest_framework/serializers.py", line 249, in data
    self._data = self.to_representation(self.instance)
                 ^^^^^^^^^^^^^^^^^^^^^^^^^^^^^^^^^^^^^
  File "/home/hader/skillswap-backend/venv/lib/python3.12/site-packages/rest_framework/serializers.py", line 713, in to_representation
    return [
           ^
  File "/home/hader/skillswap-backend/venv/lib/python3.12/site-packages/django/db/models/query.py", line 400, in __iter__
    self._fetch_all()
  File "/home/hader/skillswap-backend/venv/lib/python3.12/site-packages/django/db/models/query.py", line 1928, in _fetch_all
    self._result_cache = list(self._iterable_class(self))
                         ^^^^^^^^^^^^^^^^^^^^^^^^^^^^^^^^
  File "/home/hader/skillswap-backend/venv/lib/python3.12/site-packages/django/db/models/query.py", line 91, in __iter__
    results = compiler.execute_sql(
              ^^^^^^^^^^^^^^^^^^^^^
  File "/home/hader/skillswap-backend/venv/lib/python3.12/site-packages/django/db/models/sql/compiler.py", line 1562, in execute_sql
    cursor.execute(sql, params)
  File "/home/hader/skillswap-backend/venv/lib/python3.12/site-packages/django/db/backends/utils.py", line 79, in execute
    return self._execute_with_wrappers(
           ^^^^^^^^^^^^^^^^^^^^^^^^^^^^
  File "/home/hader/skillswap-backend/venv/lib/python3.12/site-packages/django/db/backends/utils.py", line 92, in _execute_with_wrappers
    return executor(sql, params, many, context)
           ^^^^^^^^^^^^^^^^^^^^^^^^^^^^^^^^^^^^
  File "/home/hader/skillswap-backend/venv/lib/python3.12/site-packages/django/db/backends/utils.py", line 100, in _execute
    with self.db.wrap_database_errors:
  File "/home/hader/skillswap-backend/venv/lib/python3.12/site-packages/django/db/utils.py", line 91, in __exit__
    raise dj_exc_value.with_traceback(traceback) from exc_value
  File "/home/hader/skillswap-backend/venv/lib/python3.12/site-packages/django/db/backends/utils.py", line 105, in _execute
    return self.cursor.execute(sql, params)
           ^^^^^^^^^^^^^^^^^^^^^^^^^^^^^^^^
django.db.utils.ProgrammingError: relation "skills_category" does not exist
LINE 1: ...."is_active", "skills_category"."created_at" FROM "skills_ca...
                                                             ^

ERROR 2025-08-09 16:39:59,886 basehttp 1341657 125208172336832 "GET /api/skills/categories/ HTTP/1.1" 500 145
WARNING 2025-08-09 16:39:59,913 log 1341657 125208172336832 Bad Request: /api/skills/
WARNING 2025-08-09 16:39:59,913 basehttp 1341657 125208172336832 "GET /api/skills/ HTTP/1.1" 400 215
WARNING 2025-08-09 16:39:59,927 log 1341657 125208172336832 Not Found: /api/accounts/users/
WARNING 2025-08-09 16:39:59,931 basehttp 1341657 125208172336832 "GET /api/accounts/users/ HTTP/1.1" 404 179
ERROR 2025-08-09 16:39:59,959 log 1341657 125208172336832 Internal Server Error: /api/points/packages/
Traceback (most recent call last):
  File "/home/hader/skillswap-backend/venv/lib/python3.12/site-packages/django/db/backends/utils.py", line 105, in _execute
    return self.cursor.execute(sql, params)
           ^^^^^^^^^^^^^^^^^^^^^^^^^^^^^^^^
psycopg2.errors.UndefinedTable: relation "points_pointspackage" does not exist
LINE 1: ...active", "points_pointspackage"."created_at" FROM "points_po...
                                                             ^


The above exception was the direct cause of the following exception:

Traceback (most recent call last):
  File "/home/hader/skillswap-backend/venv/lib/python3.12/site-packages/django/core/handlers/exception.py", line 55, in inner
    response = get_response(request)
               ^^^^^^^^^^^^^^^^^^^^^
  File "/home/hader/skillswap-backend/venv/lib/python3.12/site-packages/django/core/handlers/base.py", line 197, in _get_response
    response = wrapped_callback(request, *callback_args, **callback_kwargs)
               ^^^^^^^^^^^^^^^^^^^^^^^^^^^^^^^^^^^^^^^^^^^^^^^^^^^^^^^^^^^^
  File "/home/hader/skillswap-backend/venv/lib/python3.12/site-packages/django/views/decorators/csrf.py", line 65, in _view_wrapper
    return view_func(request, *args, **kwargs)
           ^^^^^^^^^^^^^^^^^^^^^^^^^^^^^^^^^^^
  File "/home/hader/skillswap-backend/venv/lib/python3.12/site-packages/django/views/generic/base.py", line 104, in view
    return self.dispatch(request, *args, **kwargs)
           ^^^^^^^^^^^^^^^^^^^^^^^^^^^^^^^^^^^^^^^
  File "/home/hader/skillswap-backend/venv/lib/python3.12/site-packages/rest_framework/views.py", line 509, in dispatch
    response = self.handle_exception(exc)
               ^^^^^^^^^^^^^^^^^^^^^^^^^^
  File "/home/hader/skillswap-backend/venv/lib/python3.12/site-packages/rest_framework/views.py", line 469, in handle_exception
    self.raise_uncaught_exception(exc)
  File "/home/hader/skillswap-backend/venv/lib/python3.12/site-packages/rest_framework/views.py", line 480, in raise_uncaught_exception
    raise exc
  File "/home/hader/skillswap-backend/venv/lib/python3.12/site-packages/rest_framework/views.py", line 506, in dispatch
    response = handler(request, *args, **kwargs)
               ^^^^^^^^^^^^^^^^^^^^^^^^^^^^^^^^^
  File "/home/hader/skillswap-backend/points/views.py", line 27, in get
    return Response(serializer.data, status=status.HTTP_200_OK)
                    ^^^^^^^^^^^^^^^
  File "/home/hader/skillswap-backend/venv/lib/python3.12/site-packages/rest_framework/serializers.py", line 795, in data
    ret = super().data
          ^^^^^^^^^^^^
  File "/home/hader/skillswap-backend/venv/lib/python3.12/site-packages/rest_framework/serializers.py", line 249, in data
    self._data = self.to_representation(self.instance)
                 ^^^^^^^^^^^^^^^^^^^^^^^^^^^^^^^^^^^^^
  File "/home/hader/skillswap-backend/venv/lib/python3.12/site-packages/rest_framework/serializers.py", line 713, in to_representation
    return [
           ^
  File "/home/hader/skillswap-backend/venv/lib/python3.12/site-packages/django/db/models/query.py", line 400, in __iter__
    self._fetch_all()
  File "/home/hader/skillswap-backend/venv/lib/python3.12/site-packages/django/db/models/query.py", line 1928, in _fetch_all
    self._result_cache = list(self._iterable_class(self))
                         ^^^^^^^^^^^^^^^^^^^^^^^^^^^^^^^^
  File "/home/hader/skillswap-backend/venv/lib/python3.12/site-packages/django/db/models/query.py", line 91, in __iter__
    results = compiler.execute_sql(
              ^^^^^^^^^^^^^^^^^^^^^
  File "/home/hader/skillswap-backend/venv/lib/python3.12/site-packages/django/db/models/sql/compiler.py", line 1562, in execute_sql
    cursor.execute(sql, params)
  File "/home/hader/skillswap-backend/venv/lib/python3.12/site-packages/django/db/backends/utils.py", line 79, in execute
    return self._execute_with_wrappers(
           ^^^^^^^^^^^^^^^^^^^^^^^^^^^^
  File "/home/hader/skillswap-backend/venv/lib/python3.12/site-packages/django/db/backends/utils.py", line 92, in _execute_with_wrappers
    return executor(sql, params, many, context)
           ^^^^^^^^^^^^^^^^^^^^^^^^^^^^^^^^^^^^
  File "/home/hader/skillswap-backend/venv/lib/python3.12/site-packages/django/db/backends/utils.py", line 100, in _execute
    with self.db.wrap_database_errors:
  File "/home/hader/skillswap-backend/venv/lib/python3.12/site-packages/django/db/utils.py", line 91, in __exit__
    raise dj_exc_value.with_traceback(traceback) from exc_value
  File "/home/hader/skillswap-backend/venv/lib/python3.12/site-packages/django/db/backends/utils.py", line 105, in _execute
    return self.cursor.execute(sql, params)
           ^^^^^^^^^^^^^^^^^^^^^^^^^^^^^^^^
django.db.utils.ProgrammingError: relation "points_pointspackage" does not exist
LINE 1: ...active", "points_pointspackage"."created_at" FROM "points_po...
                                                             ^

ERROR 2025-08-09 16:39:59,960 basehttp 1341657 125208172336832 "GET /api/points/packages/ HTTP/1.1" 500 145
INFO 2025-08-09 16:40:17,985 basehttp 1341657 125208172336832 "GET /api/ HTTP/1.1" 200 1553
ERROR 2025-08-09 16:40:18,008 log 1341657 125208172336832 Internal Server Error: /api/skills/categories/
Traceback (most recent call last):
  File "/home/hader/skillswap-backend/venv/lib/python3.12/site-packages/django/db/backends/utils.py", line 105, in _execute
    return self.cursor.execute(sql, params)
           ^^^^^^^^^^^^^^^^^^^^^^^^^^^^^^^^
psycopg2.errors.UndefinedTable: relation "skills_category" does not exist
LINE 1: ...."is_active", "skills_category"."created_at" FROM "skills_ca...
                                                             ^


The above exception was the direct cause of the following exception:

Traceback (most recent call last):
  File "/home/hader/skillswap-backend/venv/lib/python3.12/site-packages/django/core/handlers/exception.py", line 55, in inner
    response = get_response(request)
               ^^^^^^^^^^^^^^^^^^^^^
  File "/home/hader/skillswap-backend/venv/lib/python3.12/site-packages/django/core/handlers/base.py", line 197, in _get_response
    response = wrapped_callback(request, *callback_args, **callback_kwargs)
               ^^^^^^^^^^^^^^^^^^^^^^^^^^^^^^^^^^^^^^^^^^^^^^^^^^^^^^^^^^^^
  File "/home/hader/skillswap-backend/venv/lib/python3.12/site-packages/django/views/decorators/csrf.py", line 65, in _view_wrapper
    return view_func(request, *args, **kwargs)
           ^^^^^^^^^^^^^^^^^^^^^^^^^^^^^^^^^^^
  File "/home/hader/skillswap-backend/venv/lib/python3.12/site-packages/django/views/generic/base.py", line 104, in view
    return self.dispatch(request, *args, **kwargs)
           ^^^^^^^^^^^^^^^^^^^^^^^^^^^^^^^^^^^^^^^
  File "/home/hader/skillswap-backend/venv/lib/python3.12/site-packages/rest_framework/views.py", line 509, in dispatch
    response = self.handle_exception(exc)
               ^^^^^^^^^^^^^^^^^^^^^^^^^^
  File "/home/hader/skillswap-backend/venv/lib/python3.12/site-packages/rest_framework/views.py", line 469, in handle_exception
    self.raise_uncaught_exception(exc)
  File "/home/hader/skillswap-backend/venv/lib/python3.12/site-packages/rest_framework/views.py", line 480, in raise_uncaught_exception
    raise exc
  File "/home/hader/skillswap-backend/venv/lib/python3.12/site-packages/rest_framework/views.py", line 506, in dispatch
    response = handler(request, *args, **kwargs)
               ^^^^^^^^^^^^^^^^^^^^^^^^^^^^^^^^^
  File "/home/hader/skillswap-backend/skills/views.py", line 53, in get
    return Response(serializer.data)
                    ^^^^^^^^^^^^^^^
  File "/home/hader/skillswap-backend/venv/lib/python3.12/site-packages/rest_framework/serializers.py", line 795, in data
    ret = super().data
          ^^^^^^^^^^^^
  File "/home/hader/skillswap-backend/venv/lib/python3.12/site-packages/rest_framework/serializers.py", line 249, in data
    self._data = self.to_representation(self.instance)
                 ^^^^^^^^^^^^^^^^^^^^^^^^^^^^^^^^^^^^^
  File "/home/hader/skillswap-backend/venv/lib/python3.12/site-packages/rest_framework/serializers.py", line 713, in to_representation
    return [
           ^
  File "/home/hader/skillswap-backend/venv/lib/python3.12/site-packages/django/db/models/query.py", line 400, in __iter__
    self._fetch_all()
  File "/home/hader/skillswap-backend/venv/lib/python3.12/site-packages/django/db/models/query.py", line 1928, in _fetch_all
    self._result_cache = list(self._iterable_class(self))
                         ^^^^^^^^^^^^^^^^^^^^^^^^^^^^^^^^
  File "/home/hader/skillswap-backend/venv/lib/python3.12/site-packages/django/db/models/query.py", line 91, in __iter__
    results = compiler.execute_sql(
              ^^^^^^^^^^^^^^^^^^^^^
  File "/home/hader/skillswap-backend/venv/lib/python3.12/site-packages/django/db/models/sql/compiler.py", line 1562, in execute_sql
    cursor.execute(sql, params)
  File "/home/hader/skillswap-backend/venv/lib/python3.12/site-packages/django/db/backends/utils.py", line 79, in execute
    return self._execute_with_wrappers(
           ^^^^^^^^^^^^^^^^^^^^^^^^^^^^
  File "/home/hader/skillswap-backend/venv/lib/python3.12/site-packages/django/db/backends/utils.py", line 92, in _execute_with_wrappers
    return executor(sql, params, many, context)
           ^^^^^^^^^^^^^^^^^^^^^^^^^^^^^^^^^^^^
  File "/home/hader/skillswap-backend/venv/lib/python3.12/site-packages/django/db/backends/utils.py", line 100, in _execute
    with self.db.wrap_database_errors:
  File "/home/hader/skillswap-backend/venv/lib/python3.12/site-packages/django/db/utils.py", line 91, in __exit__
    raise dj_exc_value.with_traceback(traceback) from exc_value
  File "/home/hader/skillswap-backend/venv/lib/python3.12/site-packages/django/db/backends/utils.py", line 105, in _execute
    return self.cursor.execute(sql, params)
           ^^^^^^^^^^^^^^^^^^^^^^^^^^^^^^^^
django.db.utils.ProgrammingError: relation "skills_category" does not exist
LINE 1: ...."is_active", "skills_category"."created_at" FROM "skills_ca...
                                                             ^

ERROR 2025-08-09 16:40:18,011 basehttp 1341657 125208172336832 "GET /api/skills/categories/ HTTP/1.1" 500 145
WARNING 2025-08-09 16:40:18,045 log 1341657 125208172336832 Bad Request: /api/skills/
WARNING 2025-08-09 16:40:18,046 basehttp 1341657 125208172336832 "GET /api/skills/ HTTP/1.1" 400 215
WARNING 2025-08-09 16:40:18,060 log 1341657 125208172336832 Not Found: /api/accounts/users/
WARNING 2025-08-09 16:40:18,060 basehttp 1341657 125208172336832 "GET /api/accounts/users/ HTTP/1.1" 404 179
INFO 2025-08-09 16:47:23,354 autoreload 1341657 125208276516992 /home/hader/skillswap-backend/skillswap/settings.py changed, reloading.
INFO 2025-08-09 16:47:23,809 autoreload 1357290 134001607471232 Watching for file changes with StatReloader
INFO 2025-08-09 16:50:28,953 autoreload 1362071 136333605683328 Watching for file changes with StatReloader
INFO 2025-08-09 17:02:42,750 autoreload 1357290 134001607471232 /home/hader/skillswap-backend/venv/lib/python3.12/site-packages/django/utils/decorators.py changed, reloading.
INFO 2025-08-09 17:02:43,656 autoreload 1378997 139924997488768 Watching for file changes with StatReloader
INFO 2025-08-09 17:08:10,272 autoreload 1378997 139924997488768 /home/hader/skillswap-backend/venv/lib/python3.12/site-packages/sqlparse/lexer.py changed, reloading.
INFO 2025-08-09 17:37:19,237 autoreload 1429971 133915407241344 Watching for file changes with StatReloader
ERROR 2025-08-09 17:37:35,988 exception 1429971 133915304171200 Invalid HTTP_HOST header: '0.0.0.0:8001'. You may need to add '0.0.0.0' to ALLOWED_HOSTS.
Traceback (most recent call last):
  File "/home/hader/skillswap-backend/venv/lib/python3.12/site-packages/django/core/handlers/exception.py", line 55, in inner
    response = get_response(request)
               ^^^^^^^^^^^^^^^^^^^^^
  File "/home/hader/skillswap-backend/venv/lib/python3.12/site-packages/django/utils/deprecation.py", line 133, in __call__
    response = self.process_request(request)
               ^^^^^^^^^^^^^^^^^^^^^^^^^^^^^
  File "/home/hader/skillswap-backend/venv/lib/python3.12/site-packages/django/middleware/common.py", line 48, in process_request
    host = request.get_host()
           ^^^^^^^^^^^^^^^^^^
  File "/home/hader/skillswap-backend/venv/lib/python3.12/site-packages/django/http/request.py", line 151, in get_host
    raise DisallowedHost(msg)
django.core.exceptions.DisallowedHost: Invalid HTTP_HOST header: '0.0.0.0:8001'. You may need to add '0.0.0.0' to ALLOWED_HOSTS.
WARNING 2025-08-09 17:37:36,042 log 1429971 133915304171200 Bad Request: /
WARNING 2025-08-09 17:37:36,043 basehttp 1429971 133915304171200 "GET / HTTP/1.1" 400 83094
ERROR 2025-08-09 17:37:36,145 exception 1429971 133915295778496 Invalid HTTP_HOST header: '0.0.0.0:8001'. You may need to add '0.0.0.0' to ALLOWED_HOSTS.
Traceback (most recent call last):
  File "/home/hader/skillswap-backend/venv/lib/python3.12/site-packages/django/core/handlers/exception.py", line 55, in inner
    response = get_response(request)
               ^^^^^^^^^^^^^^^^^^^^^
  File "/home/hader/skillswap-backend/venv/lib/python3.12/site-packages/django/utils/deprecation.py", line 133, in __call__
    response = self.process_request(request)
               ^^^^^^^^^^^^^^^^^^^^^^^^^^^^^
  File "/home/hader/skillswap-backend/venv/lib/python3.12/site-packages/django/middleware/common.py", line 48, in process_request
    host = request.get_host()
           ^^^^^^^^^^^^^^^^^^
  File "/home/hader/skillswap-backend/venv/lib/python3.12/site-packages/django/http/request.py", line 151, in get_host
    raise DisallowedHost(msg)
django.core.exceptions.DisallowedHost: Invalid HTTP_HOST header: '0.0.0.0:8001'. You may need to add '0.0.0.0' to ALLOWED_HOSTS.
WARNING 2025-08-09 17:37:36,182 log 1429971 133915295778496 Bad Request: /favicon.ico
WARNING 2025-08-09 17:37:36,183 basehttp 1429971 133915295778496 "GET /favicon.ico HTTP/1.1" 400 83054
INFO 2025-08-09 17:41:34,973 autoreload 1429971 133915407241344 /home/hader/skillswap-backend/skillswap/settings_staging.py changed, reloading.
INFO 2025-08-09 17:41:35,845 autoreload 1435803 140283112861824 Watching for file changes with StatReloader
INFO 2025-08-09 17:41:42,690 autoreload 1435939 134535564583040 Watching for file changes with StatReloader
ERROR 2025-08-09 17:41:58,985 exception 1435939 134535461377728 Invalid HTTP_HOST header: '0.0.0.0:8001'. You may need to add '0.0.0.0' to ALLOWED_HOSTS.
Traceback (most recent call last):
  File "/home/hader/skillswap-backend/venv/lib/python3.12/site-packages/django/core/handlers/exception.py", line 55, in inner
    response = get_response(request)
               ^^^^^^^^^^^^^^^^^^^^^
  File "/home/hader/skillswap-backend/venv/lib/python3.12/site-packages/django/utils/deprecation.py", line 133, in __call__
    response = self.process_request(request)
               ^^^^^^^^^^^^^^^^^^^^^^^^^^^^^
  File "/home/hader/skillswap-backend/venv/lib/python3.12/site-packages/django/middleware/common.py", line 48, in process_request
    host = request.get_host()
           ^^^^^^^^^^^^^^^^^^
  File "/home/hader/skillswap-backend/venv/lib/python3.12/site-packages/django/http/request.py", line 151, in get_host
    raise DisallowedHost(msg)
django.core.exceptions.DisallowedHost: Invalid HTTP_HOST header: '0.0.0.0:8001'. You may need to add '0.0.0.0' to ALLOWED_HOSTS.
WARNING 2025-08-09 17:41:59,020 log 1435939 134535461377728 Bad Request: /
WARNING 2025-08-09 17:41:59,020 basehttp 1435939 134535461377728 "GET / HTTP/1.1" 400 83094
ERROR 2025-08-09 17:41:59,116 exception 1435939 134535452985024 Invalid HTTP_HOST header: '0.0.0.0:8001'. You may need to add '0.0.0.0' to ALLOWED_HOSTS.
Traceback (most recent call last):
  File "/home/hader/skillswap-backend/venv/lib/python3.12/site-packages/django/core/handlers/exception.py", line 55, in inner
    response = get_response(request)
               ^^^^^^^^^^^^^^^^^^^^^
  File "/home/hader/skillswap-backend/venv/lib/python3.12/site-packages/django/utils/deprecation.py", line 133, in __call__
    response = self.process_request(request)
               ^^^^^^^^^^^^^^^^^^^^^^^^^^^^^
  File "/home/hader/skillswap-backend/venv/lib/python3.12/site-packages/django/middleware/common.py", line 48, in process_request
    host = request.get_host()
           ^^^^^^^^^^^^^^^^^^
  File "/home/hader/skillswap-backend/venv/lib/python3.12/site-packages/django/http/request.py", line 151, in get_host
    raise DisallowedHost(msg)
django.core.exceptions.DisallowedHost: Invalid HTTP_HOST header: '0.0.0.0:8001'. You may need to add '0.0.0.0' to ALLOWED_HOSTS.
WARNING 2025-08-09 17:41:59,136 log 1435939 134535452985024 Bad Request: /favicon.ico
WARNING 2025-08-09 17:41:59,137 basehttp 1435939 134535452985024 "GET /favicon.ico HTTP/1.1" 400 83054
